[ERROR] Crash when training model with theano
Traceback (most recent call last):
  File "D:\anaconda3\envs\muffin\lib\site-packages\theano\compile\function_module.py", line 903, in __call__
    self.fn() if output_subset is None else\
ValueError: Dimension 0 in Rebroadcast's input was supposed to be 1 (got 10 instead)

During handling of the above exception, another exception occurred:

Traceback (most recent call last):
  File "D:\BigChuangMission\Muffin\src\incons_detection\train.py", line 231, in <module>
    layers_outputs_value = __get_outputs(model, input_objects_names, x, flags.outputs_dir)
  File "D:\BigChuangMission\Muffin\src\incons_detection\train.py", line 40, in __get_outputs
    layers_outputs = get_layer_output(x + [1])
  File "D:\anaconda3\envs\muffin\lib\site-packages\keras\backend\theano_backend.py", line 1430, in __call__
    outputs = self.function(*inputs)
  File "D:\anaconda3\envs\muffin\lib\site-packages\theano\compile\function_module.py", line 917, in __call__
    storage_map=getattr(self.fn, 'storage_map', None))
  File "D:\anaconda3\envs\muffin\lib\site-packages\theano\gof\link.py", line 325, in raise_with_op
    reraise(exc_type, exc_value, exc_trace)
  File "D:\anaconda3\envs\muffin\lib\site-packages\six.py", line 718, in reraise
    raise value.with_traceback(tb)
  File "D:\anaconda3\envs\muffin\lib\site-packages\theano\compile\function_module.py", line 903, in __call__
    self.fn() if output_subset is None else\
ValueError: Dimension 0 in Rebroadcast's input was supposed to be 1 (got 10 instead)
Apply node that caused the error: Rebroadcast{1}(Alloc.0)
Toposort index: 35
Inputs types: [TensorType(float32, matrix)]
Inputs shapes: [(10, 224)]
Inputs strides: [(896, 4)]
Inputs values: ['not shown']
Outputs clients: [[Elemwise{Composite{(((i0 - i1) * i2 * i3) + i4)}}(if{inplace}.0, mean, Rebroadcast{1}.0, Elemwise{Composite{inv(sqrt(((i0 / i1) + i2)))}}[(0, 0)].0, Rebroadcast{1}.0)]]

Backtrace when the node is created(use Theano flag traceback.limit=N to make it longer):
  File "D:\anaconda3\envs\muffin\lib\site-packages\keras\engine\saving.py", line 627, in model_from_config
    return deserialize(config, custom_objects=custom_objects)
  File "D:\anaconda3\envs\muffin\lib\site-packages\keras\layers\__init__.py", line 168, in deserialize
    printable_module_name='layer')
  File "D:\anaconda3\envs\muffin\lib\site-packages\keras\utils\generic_utils.py", line 147, in deserialize_keras_object
    list(custom_objects.items())))
  File "D:\anaconda3\envs\muffin\lib\site-packages\keras\engine\network.py", line 1075, in from_config
    process_node(layer, node_data)
  File "D:\anaconda3\envs\muffin\lib\site-packages\keras\engine\network.py", line 1025, in process_node
    layer(unpack_singleton(input_tensors), **kwargs)
  File "D:\anaconda3\envs\muffin\lib\site-packages\keras\engine\base_layer.py", line 489, in __call__
    output = self.call(inputs, **kwargs)
  File "D:\anaconda3\envs\muffin\lib\site-packages\keras\layers\normalization.py", line 185, in call
    epsilon=self.epsilon)
  File "D:\anaconda3\envs\muffin\lib\site-packages\keras\backend\theano_backend.py", line 794, in normalize_batch_in_training
    x, gamma, beta, reduction_axes, epsilon)

HINT: Use the Theano flag 'exception_verbosity=high' for a debugprint and storage map footprint of this apply node.


